Workbook

Sheet Summe_Punkte
A1: Platzierung | B1: Name | C1: Flunkyball | D1: Beerpong | E1: Flipcup | F1: Gesamtpunkte
A2: 1 | B2: Jonas | C2: =SUMIFS(Database!B:B,Database!A:A,B2) + SUMIFS(Database!C:C,Database!A:A,B2) -> 340 | D2: =SUMIFS(Database!B:B,Database!A:A,B2) + SUMIFS(Database!D:D,Database!A:A,B2) -> 380 | E2: =SUMIFS(Database!B:B,Database!A:A,B2) + SUMIFS(Database!E:E,Database!A:A,B2) -> 290 | F2: =SUMIFS(Database!B:B,Database!A:A,B2) + SUMIFS(Database!F:F,Database!A:A,B2) -> 390
A3: 2 | B3: Richard | C3: =SUMIFS(Database!B:B,Database!A:A,B3) + SUMIFS(Database!C:C,Database!A:A,B3) -> 320 | D3: =SUMIFS(Database!B:B,Database!A:A,B3) + SUMIFS(Database!D:D,Database!A:A,B3) -> 380 | E3: =SUMIFS(Database!B:B,Database!A:A,B3) + SUMIFS(Database!E:E,Database!A:A,B3) -> 290 | F3: =SUMIFS(Database!B:B,Database!A:A,B3) + SUMIFS(Database!F:F,Database!A:A,B3) -> 340
A4: 3 | B4: Jannes | C4: =SUMIFS(Database!B:B,Database!A:A,B4) + SUMIFS(Database!C:C,Database!A:A,B4) -> 270 | D4: =SUMIFS(Database!B:B,Database!A:A,B4) + SUMIFS(Database!D:D,Database!A:A,B4) -> 280 | E4: =SUMIFS(Database!B:B,Database!A:A,B4) + SUMIFS(Database!E:E,Database!A:A,B4) -> 230 | F4: =SUMIFS(Database!B:B,Database!A:A,B4) + SUMIFS(Database!F:F,Database!A:A,B4) -> 300
A5: 4 | B5: Hannah | C5: =SUMIFS(Database!B:B,Database!A:A,B5) + SUMIFS(Database!C:C,Database!A:A,B5) -> 240 | D5: =SUMIFS(Database!B:B,Database!A:A,B5) + SUMIFS(Database!D:D,Database!A:A,B5) -> 180 | E5: =SUMIFS(Database!B:B,Database!A:A,B5) + SUMIFS(Database!E:E,Database!A:A,B5) -> 390 | F5: =SUMIFS(Database!B:B,Database!A:A,B5) + SUMIFS(Database!F:F,Database!A:A,B5) -> 270
A6: 5 | B6: Till | C6: =SUMIFS(Database!B:B,Database!A:A,B6) + SUMIFS(Database!C:C,Database!A:A,B6) -> 230 | D6: =SUMIFS(Database!B:B,Database!A:A,B6) + SUMIFS(Database!D:D,Database!A:A,B6) -> 180 | E6: =SUMIFS(Database!B:B,Database!A:A,B6) + SUMIFS(Database!E:E,Database!A:A,B6) -> 240 | F6: =SUMIFS(Database!B:B,Database!A:A,B6) + SUMIFS(Database!F:F,Database!A:A,B6) -> 260
A7: 6 | B7: Georg | C7: =SUMIFS(Database!B:B,Database!A:A,B7) + SUMIFS(Database!C:C,Database!A:A,B7) -> 210 | D7: =SUMIFS(Database!B:B,Database!A:A,B7) + SUMIFS(Database!D:D,Database!A:A,B7) -> 220 | E7: =SUMIFS(Database!B:B,Database!A:A,B7) + SUMIFS(Database!E:E,Database!A:A,B7) -> 220 | F7: =SUMIFS(Database!B:B,Database!A:A,B7) + SUMIFS(Database!F:F,Database!A:A,B7) -> 240
A8: 7 | B8: Elias | C8: =SUMIFS(Database!B:B,Database!A:A,B8) + SUMIFS(Database!C:C,Database!A:A,B8) -> 260 | D8: =SUMIFS(Database!B:B,Database!A:A,B8) + SUMIFS(Database!D:D,Database!A:A,B8) -> 170 | E8: =SUMIFS(Database!B:B,Database!A:A,B8) + SUMIFS(Database!E:E,Database!A:A,B8) -> 190 | F8: =SUMIFS(Database!B:B,Database!A:A,B8) + SUMIFS(Database!F:F,Database!A:A,B8) -> 230
A9: 8 | B9: Roman | C9: =SUMIFS(Database!B:B,Database!A:A,B9) + SUMIFS(Database!C:C,Database!A:A,B9) -> 160 | D9: =SUMIFS(Database!B:B,Database!A:A,B9) + SUMIFS(Database!D:D,Database!A:A,B9) -> 200 | E9: =SUMIFS(Database!B:B,Database!A:A,B9) + SUMIFS(Database!E:E,Database!A:A,B9) -> 230 | F9: =SUMIFS(Database!B:B,Database!A:A,B9) + SUMIFS(Database!F:F,Database!A:A,B9) -> 210
A10: 9 | B10: Carl | C10: =SUMIFS(Database!B:B,Database!A:A,B10) + SUMIFS(Database!C:C,Database!A:A,B10) -> 130 | D10: =SUMIFS(Database!B:B,Database!A:A,B10) + SUMIFS(Database!D:D,Database!A:A,B10) -> 130 | E10: =SUMIFS(Database!B:B,Database!A:A,B10) + SUMIFS(Database!E:E,Database!A:A,B10) -> 150 | F10: =SUMIFS(Database!B:B,Database!A:A,B10) + SUMIFS(Database!F:F,Database!A:A,B10) -> 160
A11: 10 | B11: Siggi | C11: =SUMIFS(Database!B:B,Database!A:A,B11) + SUMIFS(Database!C:C,Database!A:A,B11) -> 160 | D11: =SUMIFS(Database!B:B,Database!A:A,B11) + SUMIFS(Database!D:D,Database!A:A,B11) -> 140 | E11: =SUMIFS(Database!B:B,Database!A:A,B11) + SUMIFS(Database!E:E,Database!A:A,B11) -> 110 | F11: =SUMIFS(Database!B:B,Database!A:A,B11) + SUMIFS(Database!F:F,Database!A:A,B11) -> 160
A12: 11 | B12: Jason | C12: =SUMIFS(Database!B:B,Database!A:A,B12) + SUMIFS(Database!C:C,Database!A:A,B12) -> 80 | D12: =SUMIFS(Database!B:B,Database!A:A,B12) + SUMIFS(Database!D:D,Database!A:A,B12) -> 140 | E12: =SUMIFS(Database!B:B,Database!A:A,B12) + SUMIFS(Database!E:E,Database!A:A,B12) -> 230 | F12: =SUMIFS(Database!B:B,Database!A:A,B12) + SUMIFS(Database!F:F,Database!A:A,B12) -> 150
A13: 12 | B13: Fabian | C13: =SUMIFS(Database!B:B,Database!A:A,B13) + SUMIFS(Database!C:C,Database!A:A,B13) -> 160 | D13: =SUMIFS(Database!B:B,Database!A:A,B13) + SUMIFS(Database!D:D,Database!A:A,B13) -> 90 | E13: =SUMIFS(Database!B:B,Database!A:A,B13) + SUMIFS(Database!E:E,Database!A:A,B13) -> 230 | F13: =SUMIFS(Database!B:B,Database!A:A,B13) + SUMIFS(Database!F:F,Database!A:A,B13) -> 150
... A36: 35 | B36: Charlie | C36: =SUMIFS(Database!B:B,Database!A:A,B36) + SUMIFS(Database!C:C,Database!A:A,B36) -> 10 | D36: =SUMIFS(Database!B:B,Database!A:A,B36) + SUMIFS(Database!D:D,Database!A:A,B36) -> 10 | E36: =SUMIFS(Database!B:B,Database!A:A,B36) + SUMIFS(Database!E:E,Database!A:A,B36) -> 10 | F36: =SUMIFS(Database!B:B,Database!A:A,B36) + SUMIFS(Database!F:F,Database!A:A,B36) -> 10

Sheet Olympiade_1
A1: Platzierung | B1: Name | C1: Flunkyball | D1: Beerpong | E1: Flipcup | F1: Flunkyball-Rank | G1: Beerpong-Rank | H1: Flipcup-Rank | I1: Gesamtpunkte
A2: 1 | B2: Richard | C2: 30 | D2: 30 | E2: 40 | F2: 2 | G2: 2 | H2: 1 | I2: 40
A3: 1 | B3: Anton | C3: 30 | D3: 30 | E3: 40 | F3: 2 | G3: 2 | H3: 1 | I3: 40
A4: 2 | B4: Georg | C4: 40 | D4: 20 | E4: 30 | F4: 1 | G4: 3 | H4: 2 | I4: 30
A5: 2 | B5: Elias | C5: 40 | D5: 20 | E5: 30 | F5: 1 | G5: 3 | H5: 2 | I5: 30
A6: 3 | B6: Jonas | C6: 10 | D6: 40 | E6: 10 | F6: 4 | G6: 1 | H6: 4 | I6: 20
A7: 3 | B7: Lorenz | C7: 10 | D7: 40 | E7: 10 | F7: 4 | G7: 1 | H7: 4 | I7: 20
A8: 4 | B8: Mo | C8: 20 | D8: 10 | E8: 20 | F8: 3 | G8: 4 | H8: 3 | I8: 10
A9: 4 | B9: Bruno | C9: 20 | D9: 10 | E9: 20 | F9: 3 | G9: 4 | H9: 3 | I9: 10

Sheet Olympiade_2
A1: Platzierung | B1: Name | C1: Flunkyball | D1: Beerpong | E1: Flipcup | F1: Flunkyball-Rank | G1: Beerpong-Rank | H1: Flipcup-Rank | I1: Gesamtpunkte
A2: 1 | B2: Jannes | C2: 40 | D2: 40 | E2: 30 | F2: 1 | G2: 1 | H2: 2 | I2: 50
A3: 1 | B3: Georg | C3: 40 | D3: 40 | E3: 30 | F3: 1 | G3: 1 | H3: 2 | I3: 50
A4: 2 | B4: Richard | C4: 40 | D4: 40 | E4: 30 | F4: 1 | G4: 1 | H4: 2 | I4: 40
A5: 2 | B5: Matthias | C5: 40 | D5: 40 | E5: 30 | F5: 1 | G5: 1 | H5: 2 | I5: 40
A6: 3 | B6: Doro | C6: 30 | D6: 30 | E6: 20 | F6: 3 | G6: 3 | H6: 3 | I6: 30
A7: 3 | B7: Basti | C7: 30 | D7: 30 | E7: 20 | F7: 3 | G7: 3 | H7: 3 | I7: 30
A8: 3 | B8: Melli | C8: 30 | D8: 30 | E8: 20 | F8: 3 | G8: 3 | H8: 3 | I8: 30
A9: 4 | B9: Jonas | C9: 20 | D9: 20 | E9: 10 | F9: 4 | G9: 4 | H9: 4 | I9: 20
A10: 4 | B10: Robin | C10: 20 | D10: 20 | E10: 10 | F10: 4 | G10: 4 | H10: 4 | I10: 20
A11: 5 | B11: Fabian | C11: 10 | D11: 10 | E11: 40 | F11: 5 | G11: 5 | H11: 1 | I11: 10
A12: 5 | B12: Hannah | C12: 10 | D12: 10 | E12: 40 | F12: 5 | G12: 5 | H12: 1 | I12: 10

Sheet Olympiade_3
A1: Platzierung | B1: Name | C1: Flunkyball | D1: Beerpong | E1: Flipcup | F1: Flunkyball-Rank | G1: Beerpong-Rank | H1: Flipcup-Rank | I1: Gesamtpunkte
A2: 1 | B2: Richard | C2: 20 | D2: 30 | E2: 50 | F2: 4 | G2: 3 | H2: 1 | I2: 50
A3: 1 | B3: Hannah | C3: 20 | D3: 30 | E3: 50 | F3: 4 | G3: 3 | H3: 1 | I3: 50
A4: 2 | B4: Lorenz | C4: 30 | D4: 50 | E4: 20 | F4: 3 | G4: 1 | H4: 4 | I4: 40
A5: 2 | B5: Roman | C5: 30 | D5: 50 | E5: 20 | F5: 3 | G5: 1 | H5: 4 | I5: 40
A6: 3 | B6: Robin | C6: 40 | D6: 10 | E6: 40 | F6: 2 | G6: 5 | H6: 2 | I6: 30
A7: 3 | B7: Jonas | C7: 40 | D7: 10 | E7: 40 | F7: 2 | G7: 5 | H7: 2 | I7: 30
A8: 4 | B8: Bruno | C8: 50 | D8: 20 | E8: 10 | F8: 1 | G8: 4 | H8: 5 | I8: 20
A9: 4 | B9: Georg | C9: 50 | D9: 20 | E9: 10 | F9: 1 | G9: 4 | H9: 5 | I9: 20
A10: 5 | B10: Anton | C10: 10 | D10: 40 | E10: 30 | F10: 5 | G10: 2 | H10: 3 | I10: 10
A11: 5 | B11: Melli | C11: 10 | D11: 40 | E11: 30 | F11: 5 | G11: 2 | H11: 3 | I11: 10

Sheet Olympiade_4
A1: Platzierung | B1: Name | C1: Flunkyball | D1: Beerpong | E1: Flipcup | F1: Flunkyball-Rank | G1: Beerpong-Rank | H1: Flipcup-Rank | I1: Gesamtpunkte
A2: 1 | B2: Richard | C2: 50 | D2: 40 | E2: 20 | F2: 1 | G2: 2 | H2: 4 | I2: 50
A3: 1 | B3: Till | C3: 50 | D3: 40 | E3: 20 | F3: 1 | G3: 2 | H3: 4 | I3: 50
A4: 2 | B4: Matthias | C4: 40 | D4: 50 | E4: 10 | F4: 2 | G4: 1 | H4: 5 | I4: 40
A5: 2 | B5: Jannes | C5: 40 | D5: 50 | E5: 10 | F5: 2 | G5: 1 | H5: 5 | I5: 40
A6: 2 | B6: Jonas | C6: 20 | D6: 30 | E6: 50 | F6: 4 | G6: 3 | H6: 1 | I6: 40
A7: 2 | B7: Fabian | C7: 20 | D7: 30 | E7: 50 | F7: 4 | G7: 3 | H7: 1 | I7: 40
A8: 4 | B8: Basti | C8: 30 | D8: 10 | E8: 40 | F8: 3 | G8: 5 | H8: 2 | I8: 20
A9: 4 | B9: Hannah | C9: 30 | D9: 10 | E9: 40 | F9: 3 | G9: 5 | H9: 2 | I9: 20
A10: 5 | B10: Robin | C10: 10 | D10: 20 | E10: 30 | F10: 5 | G10: 4 | H10: 3 | I10: 10
A11: 5 | B11: Oskar | C11: 10 | D11: 20 | E11: 30 | F11: 5 | G11: 4 | H11: 3 | I11: 10

Sheet Olympiade_5
A1: Platzierung | B1: Name | C1: Flunkyball | D1: Beerpong | E1: Flipcup | F1: Flunkyball-Rank | G1: Beerpong-Rank | H1: Flipcup-Rank | I1: Gesamtpunkte
A2: 1 | B2: Georg | C2: 50 | D2: 70 | E2: 80 | F2: 4 | G2: 2 | H2: 1 | I2: 80
A3: 1 | B3: Hannah | C3: 50 | D3: 70 | E3: 80 | F3: 4 | G3: 2 | H3: 1 | I3: 80
A4: 2 | B4: Jonas | C4: 80 | D4: 80 | E4: 20 | F4: 1 | G4: 1 | H4: 7 | I4: 70
A5: 2 | B5: Bruno | C5: 80 | D5: 80 | E5: 20 | F5: 1 | G5: 1 | H5: 7 | I5: 70
A6: 2 | B6: Till | C6: 70 | D6: 50 | E6: 60 | F6: 2 | G6: 4 | H6: 3 | I6: 70
A7: 2 | B7: Anna | C7: 70 | D7: 50 | E7: 60 | F7: 2 | G7: 4 | H7: 3 | I7: 70
A8: 4 | B8: Lina | C8: 60 | D8: 60 | E8: 50 | F8: 3 | G8: 3 | H8: 4 | I8: 50
A9: 4 | B9: Jochen | C9: 60 | D9: 60 | E9: 50 | F9: 3 | G9: 3 | H9: 4 | I9: 50
A10: 5 | B10: Elias | C10: 40 | D10: 20 | E10: 70 | F10: 5 | G10: 7 | H10: 2 | I10: 40
A11: 5 | B11: Amelie | C11: 40 | D11: 20 | E11: 70 | F11: 5 | G11: 7 | H11: 2 | I11: 40
A12: 6 | B12: Jannes | C12: 30 | D12: 30 | E12: 40 | F12: 6 | G12: 6 | H12: 5 | I12: 30
A13: 6 | B13: Roman | C13: 30 | D13: 30 | E13: 40 | F13: 6 | G13: 6 | H13: 5 | I13: 30
... A17: 8 | B17: Charlie | C17: 10 | D17: 10 | E17: 10 | F17: 8 | G17: 8 | H17: 8 | I17: 10

Sheet Olympiade_6
A1: Platzierung | B1: Name | C1: Flunkyball | D1: Beerpong | E1: Flipcup | F1: Flunkyball-Rank | G1: Beerpong-Rank | H1: Flipcup-Rank | I1: Gesamtpunkte
A2: 1 | B2: Till | C2: 90 | D2: 50 | E2: 80 | F2: 1 | G2: 5 | H2: 2 | I2: 90
A3: 1 | B3: Elias | C3: 90 | D3: 50 | E3: 80 | F3: 1 | G3: 5 | H3: 2 | I3: 90
A4: 2 | B4: Jannes | C4: 60 | D4: 90 | E4: 40 | F4: 4 | G4: 1 | H4: 6 | I4: 80
A5: 2 | B5: Marc | C5: 60 | D5: 90 | E5: 40 | F5: 4 | G5: 1 | H5: 6 | I5: 80
A6: 3 | B6: Hannah | C6: 70 | D6: 40 | E6: 70 | F6: 3 | G6: 6 | H6: 3 | I6: 70
A7: 3 | B7: Carl | C7: 70 | D7: 40 | E7: 70 | F7: 3 | G7: 6 | H7: 3 | I7: 70
A8: 4 | B8: Jonas | C8: 20 | D8: 80 | E8: 60 | F8: 8 | G8: 2 | H8: 4 | I8: 60
A9: 4 | B9: Doro | C9: 20 | D9: 80 | E9: 60 | F9: 8 | G9: 2 | H9: 4 | I9: 60
A10: 5 | B10: Roman | C10: 40 | D10: 30 | E10: 90 | F10: 6 | G10: 7 | H10: 1 | I10: 50
A11: 5 | B11: Jason | C11: 40 | D11: 30 | E11: 90 | F11: 6 | G11: 7 | H11: 1 | I11: 50
A12: 6 | B12: Richard | C12: 50 | D12: 70 | E12: 30 | F12: 5 | G12: 3 | H12: 7 | I12: 40
A13: 6 | B13: Robin | C13: 50 | D13: 70 | E13: 30 | F13: 5 | G13: 3 | H13: 7 | I13: 40
... A19: 9 | B19: Artur | C19: 10 | D19: 20 | E19: 20 | F19: 9 | G19: 8 | H19: 8 | I19: 10

Sheet Olympiade_7
A1: Platzierung | B1: Name | C1: Flunkyball | D1: Beerpong | E1: Flipcup | F1: Flunkyball-Rank | G1: Beerpong-Rank | H1: Flipcup-Rank | I1: Gesamtpunkte
A2: 1 | B2: Siggi | C2: 80 | D2: 80 | E2: 60 | F2: 1 | G2: 1 | H2: 3 | I2: 80
A3: 1 | B3: Richard | C3: 80 | D3: 80 | E3: 60 | F3: 1 | G3: 1 | H3: 3 | I3: 80
A4: 2 | B4: Theo | C4: 70 | D4: 60 | E4: 50 | F4: 2 | G4: 3 | H4: 4 | I4: 70
A5: 2 | B5: Jonas | C5: 70 | D5: 60 | E5: 50 | F5: 2 | G5: 3 | H5: 4 | I5: 70
A6: 3 | B6: Melli | C6: 30 | D6: 70 | E6: 70 | F6: 6 | G6: 2 | H6: 2 | I6: 60
A7: 3 | B7: Georg | C7: 30 | D7: 70 | E7: 70 | F7: 6 | G7: 2 | H7: 2 | I7: 60
A8: 4 | B8: Jason | C8: 20 | D8: 40 | E8: 80 | F8: 7 | G8: 5 | H8: 1 | I8: 50
A9: 4 | B9: Till | C9: 20 | D9: 40 | E9: 80 | F9: 7 | G9: 5 | H9: 1 | I9: 50
A10: 5 | B10: Bruno | C10: 60 | D10: 20 | E10: 30 | F10: 3 | G10: 7 | H10: 6 | I10: 40
A11: 5 | B11: Oskar | C11: 60 | D11: 20 | E11: 30 | F11: 3 | G11: 7 | H11: 6 | I11: 40
A12: 6 | B12: Jannes | C12: 50 | D12: 30 | E12: 20 | F12: 4 | G12: 6 | H12: 7 | I12: 30
A13: 6 | B13: Marc | C13: 50 | D13: 30 | E13: 20 | F13: 4 | G13: 6 | H13: 7 | I13: 30
... A17: 8 | B17: Amelie | C17: 10 | D17: 10 | E17: 40 | F17: 8 | G17: 8 | H17: 5 | I17: 10

Sheet Olympiade_8
A1: Platzierung | B1: Name | C1: Flunkyball | D1: Beerpong | E1: Flipcup | F1: Flunkyball-Rank | G1: Beerpong-Rank | H1: Flipcup-Rank | I1: Gesamtpunkte
A2: 1 | B2: Roman | C2: 60 | D2: 90 | E2: 80 | F2: 4 | G2: 1 | H2: 2 | I2: 90
A3: 1 | B3: Carl | C3: 60 | D3: 90 | E3: 80 | F3: 4 | G3: 1 | H3: 2 | I3: 90
A4: 2 | B4: Siggi | C4: 80 | D4: 60 | E4: 50 | F4: 2 | G4: 4 | H4: 5 | I4: 80
A5: 2 | B5: Jonas | C5: 80 | D5: 60 | E5: 50 | F5: 2 | G5: 4 | H5: 5 | I5: 80
A6: 3 | B6: Elias | C6: 90 | D6: 80 | E6: 10 | F6: 1 | G6: 2 | H6: 9 | I6: 70
A7: 3 | B7: Mo | C7: 90 | D7: 80 | E7: 10 | F7: 1 | G7: 2 | H7: 9 | I7: 70
A8: 3 | B8: Jannes | C8: 50 | D8: 40 | E8: 90 | F8: 5 | G8: 6 | H8: 1 | I8: 70
A9: 3 | B9: Fabian | C9: 50 | D9: 40 | E9: 90 | F9: 5 | G9: 6 | H9: 1 | I9: 70
A10: 5 | B10: Luisa | C10: 20 | D10: 70 | E10: 60 | F10: 8 | G10: 3 | H10: 4 | I10: 50
A11: 5 | B11: Jason | C11: 20 | D11: 70 | E11: 60 | F11: 8 | G11: 3 | H11: 4 | I11: 50
A12: 6 | B12: Tim | C12: 70 | D12: 20 | E12: 40 | F12: 3 | G12: 8 | H12: 6 | I12: 40
A13: 6 | B13: Oskar | C13: 70 | D13: 20 | E13: 40 | F13: 3 | G13: 8 | H13: 6 | I13: 40
... A19: 9 | B19: Lorenz | C19: 10 | D19: 30 | E19: 20 | F19: 9 | G19: 7 | H19: 8 | I19: 10

Sheet Durchschnitt
D2: Spieleranzahl | G2: 4 | H2: 5 | I2: 5 | J2: 5 | K2: 8 | L2: 9 | M2: 8 | N2: 9
B3: Gesamtplatzierung | C3: Durchschnittsplatzierung | D3: Name | E3: Teilgenommen | F3: Durchschnittswert | G3: 1 | H3: 2 | I3: 3 | J3: 4 | K3: 5 | L3: 6 | M3: 7 | N3: 8
B4: 1 | C4: =IF(ISNUMBER(Durchschnitt!$F4)=TRUE(),_xlfn.RANK.EQ(Durchschnitt!$F4,Durchschnitt!$F$4:$F$36,0),"") -> 2 | D4: Richard | E4: =COUNT(G4:M4) -> 7 | F4: =IF(Durchschnitt!$E4>=3,AVERAGE(G4:M4),"") -> 0.75255102 | G4: =IF('Platzierungen alle Olympiaden'!$E4=0,"",(G$2-'Platzierungen alle Olympiaden'!$E4)/(G$2-1)) -> 1 | H4: =IF('Platzierungen alle Olympiaden'!$F4=0,"",(H$2-'Platzierungen alle Olympiaden'!$F4)/(H$2-1)) -> 0.75 | I4: =IF('Platzierungen alle Olympiaden'!$G4=0,"",(I$2-'Platzierungen alle Olympiaden'!$G4)/(I$2-1)) -> 1 | J4: =IF('Platzierungen alle Olympiaden'!$H4=0,"",(J$2-'Platzierungen alle Olympiaden'!$H4)/(J$2-1)) -> 1 | K4: =IF('Platzierungen alle Olympiaden'!$I4=0,"",(K$2-'Platzierungen alle Olympiaden'!$I4)/(K$2-1)) -> 0.14285714 | L4: =IF('Platzierungen alle Olympiaden'!$J4=0,"",(L$2-'Platzierungen alle Olympiaden'!$J4)/(L$2-1)) -> 0.375 | M4: =IF('Platzierungen alle Olympiaden'!$K4=0,"",(M$2-'Platzierungen alle Olympiaden'!$K4)/(M$2-1)) -> 1
B5: 2 | C5: =IF(ISNUMBER(Durchschnitt!$F5)=TRUE(),_xlfn.RANK.EQ(Durchschnitt!$F5,Durchschnitt!$F$4:$F$36,0),"") -> 6 | D5: Jonas | E5: =COUNT(G5:M5) -> 7 | F5: =IF(Durchschnitt!$E5>=3,AVERAGE(G5:M5),"") -> 0.59608844 | G5: =IF('Platzierungen alle Olympiaden'!$E5=0,"",(G$2-'Platzierungen alle Olympiaden'!$E5)/(G$2-1)) -> 0.33333333 | H5: =IF('Platzierungen alle Olympiaden'!$F5=0,"",(H$2-'Platzierungen alle Olympiaden'!$F5)/(H$2-1)) -> 0.25 | I5: =IF('Platzierungen alle Olympiaden'!$G5=0,"",(I$2-'Platzierungen alle Olympiaden'!$G5)/(I$2-1)) -> 0.5 | J5: =IF('Platzierungen alle Olympiaden'!$H5=0,"",(J$2-'Platzierungen alle Olympiaden'!$H5)/(J$2-1)) -> 0.75 | K5: =IF('Platzierungen alle Olympiaden'!$I5=0,"",(K$2-'Platzierungen alle Olympiaden'!$I5)/(K$2-1)) -> 0.85714286 | L5: =IF('Platzierungen alle Olympiaden'!$J5=0,"",(L$2-'Platzierungen alle Olympiaden'!$J5)/(L$2-1)) -> 0.625 | M5: =IF('Platzierungen alle Olympiaden'!$K5=0,"",(M$2-'Platzierungen alle Olympiaden'!$K5)/(M$2-1)) -> 0.85714286
B6: 3 | C6: =IF(ISNUMBER(Durchschnitt!$F6)=TRUE(),_xlfn.RANK.EQ(Durchschnitt!$F6,Durchschnitt!$F$4:$F$36,0),"") -> 1 | D6: Till | E6: =COUNT(G6:M6) -> 4 | F6: =IF(Durchschnitt!$E6>=3,AVERAGE(G6:M6),"") -> 0.85714286 | G6: =IF('Platzierungen alle Olympiaden'!$E6=0,"",(G$2-'Platzierungen alle Olympiaden'!$E6)/(G$2-1)) | H6: =IF('Platzierungen alle Olympiaden'!$F6=0,"",(H$2-'Platzierungen alle Olympiaden'!$F6)/(H$2-1)) | I6: =IF('Platzierungen alle Olympiaden'!$G6=0,"",(I$2-'Platzierungen alle Olympiaden'!$G6)/(I$2-1)) | J6: =IF('Platzierungen alle Olympiaden'!$H6=0,"",(J$2-'Platzierungen alle Olympiaden'!$H6)/(J$2-1)) -> 1 | K6: =IF('Platzierungen alle Olympiaden'!$I6=0,"",(K$2-'Platzierungen alle Olympiaden'!$I6)/(K$2-1)) -> 0.85714286 | L6: =IF('Platzierungen alle Olympiaden'!$J6=0,"",(L$2-'Platzierungen alle Olympiaden'!$J6)/(L$2-1)) -> 1 | M6: =IF('Platzierungen alle Olympiaden'!$K6=0,"",(M$2-'Platzierungen alle Olympiaden'!$K6)/(M$2-1)) -> 0.57142857
B7: 4 | C7: =IF(ISNUMBER(Durchschnitt!$F7)=TRUE(),_xlfn.RANK.EQ(Durchschnitt!$F7,Durchschnitt!$F$4:$F$36,0),"") -> 3 | D7: Georg | E7: =COUNT(G7:M7) -> 5 | F7: =IF(Durchschnitt!$E7>=3,AVERAGE(G7:M7),"") -> 0.72619048 | G7: =IF('Platzierungen alle Olympiaden'!$E7=0,"",(G$2-'Platzierungen alle Olympiaden'!$E7)/(G$2-1)) -> 0.66666667 | H7: =IF('Platzierungen alle Olympiaden'!$F7=0,"",(H$2-'Platzierungen alle Olympiaden'!$F7)/(H$2-1)) -> 1 | I7: =IF('Platzierungen alle Olympiaden'!$G7=0,"",(I$2-'Platzierungen alle Olympiaden'!$G7)/(I$2-1)) -> 0.25 | J7: =IF('Platzierungen alle Olympiaden'!$H7=0,"",(J$2-'Platzierungen alle Olympiaden'!$H7)/(J$2-1)) | K7: =IF('Platzierungen alle Olympiaden'!$I7=0,"",(K$2-'Platzierungen alle Olympiaden'!$I7)/(K$2-1)) -> 1 | L7: =IF('Platzierungen alle Olympiaden'!$J7=0,"",(L$2-'Platzierungen alle Olympiaden'!$J7)/(L$2-1)) | M7: =IF('Platzierungen alle Olympiaden'!$K7=0,"",(M$2-'Platzierungen alle Olympiaden'!$K7)/(M$2-1)) -> 0.71428571
B8: 5 | C8: =IF(ISNUMBER(Durchschnitt!$F8)=TRUE(),_xlfn.RANK.EQ(Durchschnitt!$F8,Durchschnitt!$F$4:$F$36,0),"") -> 8 | D8: Hannah | E8: =COUNT(G8:M8) -> 6 | F8: =IF(Durchschnitt!$E8>=3,AVERAGE(G8:M8),"") -> 0.5 | G8: =IF('Platzierungen alle Olympiaden'!$E8=0,"",(G$2-'Platzierungen alle Olympiaden'!$E8)/(G$2-1)) | H8: =IF('Platzierungen alle Olympiaden'!$F8=0,"",(H$2-'Platzierungen alle Olympiaden'!$F8)/(H$2-1)) -> 0 | I8: =IF('Platzierungen alle Olympiaden'!$G8=0,"",(I$2-'Platzierungen alle Olympiaden'!$G8)/(I$2-1)) -> 1 | J8: =IF('Platzierungen alle Olympiaden'!$H8=0,"",(J$2-'Platzierungen alle Olympiaden'!$H8)/(J$2-1)) -> 0.25 | K8: =IF('Platzierungen alle Olympiaden'!$I8=0,"",(K$2-'Platzierungen alle Olympiaden'!$I8)/(K$2-1)) -> 1 | L8: =IF('Platzierungen alle Olympiaden'!$J8=0,"",(L$2-'Platzierungen alle Olympiaden'!$J8)/(L$2-1)) -> 0.75 | M8: =IF('Platzierungen alle Olympiaden'!$K8=0,"",(M$2-'Platzierungen alle Olympiaden'!$K8)/(M$2-1)) -> 0
B9: 6 | C9: =IF(ISNUMBER(Durchschnitt!$F9)=TRUE(),_xlfn.RANK.EQ(Durchschnitt!$F9,Durchschnitt!$F$4:$F$36,0),"") -> 5 | D9: Jannes | E9: =COUNT(G9:M9) -> 5 | F9: =IF(Durchschnitt!$E9>=3,AVERAGE(G9:M9),"") -> 0.63928571 | G9: =IF('Platzierungen alle Olympiaden'!$E9=0,"",(G$2-'Platzierungen alle Olympiaden'!$E9)/(G$2-1)) | H9: =IF('Platzierungen alle Olympiaden'!$F9=0,"",(H$2-'Platzierungen alle Olympiaden'!$F9)/(H$2-1)) -> 1 | I9: =IF('Platzierungen alle Olympiaden'!$G9=0,"",(I$2-'Platzierungen alle Olympiaden'!$G9)/(I$2-1)) | J9: =IF('Platzierungen alle Olympiaden'!$H9=0,"",(J$2-'Platzierungen alle Olympiaden'!$H9)/(J$2-1)) -> 0.75 | K9: =IF('Platzierungen alle Olympiaden'!$I9=0,"",(K$2-'Platzierungen alle Olympiaden'!$I9)/(K$2-1)) -> 0.28571429 | L9: =IF('Platzierungen alle Olympiaden'!$J9=0,"",(L$2-'Platzierungen alle Olympiaden'!$J9)/(L$2-1)) -> 0.875 | M9: =IF('Platzierungen alle Olympiaden'!$K9=0,"",(M$2-'Platzierungen alle Olympiaden'!$K9)/(M$2-1)) -> 0.28571429
B10: 7 | C10: =IF(ISNUMBER(Durchschnitt!$F10)=TRUE(),_xlfn.RANK.EQ(Durchschnitt!$F10,Durchschnitt!$F$4:$F$36,0),"") -> 4 | D10: Elias | E10: =COUNT(G10:M10) -> 3 | F10: =IF(Durchschnitt!$E10>=3,AVERAGE(G10:M10),"") -> 0.6984127 | G10: =IF('Platzierungen alle Olympiaden'!$E10=0,"",(G$2-'Platzierungen alle Olympiaden'!$E10)/(G$2-1)) -> 0.66666667 | H10: =IF('Platzierungen alle Olympiaden'!$F10=0,"",(H$2-'Platzierungen alle Olympiaden'!$F10)/(H$2-1)) | I10: =IF('Platzierungen alle Olympiaden'!$G10=0,"",(I$2-'Platzierungen alle Olympiaden'!$G10)/(I$2-1)) | J10: =IF('Platzierungen alle Olympiaden'!$H10=0,"",(J$2-'Platzierungen alle Olympiaden'!$H10)/(J$2-1)) | K10: =IF('Platzierungen alle Olympiaden'!$I10=0,"",(K$2-'Platzierungen alle Olympiaden'!$I10)/(K$2-1)) -> 0.42857143 | L10: =IF('Platzierungen alle Olympiaden'!$J10=0,"",(L$2-'Platzierungen alle Olympiaden'!$J10)/(L$2-1)) -> 1 | M10: =IF('Platzierungen alle Olympiaden'!$K10=0,"",(M$2-'Platzierungen alle Olympiaden'!$K10)/(M$2-1))
B11: 8 | C11: =IF(ISNUMBER(Durchschnitt!$F11)=TRUE(),_xlfn.RANK.EQ(Durchschnitt!$F11,Durchschnitt!$F$4:$F$36,0),"") -> 10 | D11: Bruno | E11: =COUNT(G11:M11) -> 4 | F11: =IF(Durchschnitt!$E11>=3,AVERAGE(G11:M11),"") -> 0.38392857 | G11: =IF('Platzierungen alle Olympiaden'!$E11=0,"",(G$2-'Platzierungen alle Olympiaden'!$E11)/(G$2-1)) -> 0 | H11: =IF('Platzierungen alle Olympiaden'!$F11=0,"",(H$2-'Platzierungen alle Olympiaden'!$F11)/(H$2-1)) | I11: =IF('Platzierungen alle Olympiaden'!$G11=0,"",(I$2-'Platzierungen alle Olympiaden'!$G11)/(I$2-1)) -> 0.25 | J11: =IF('Platzierungen alle Olympiaden'!$H11=0,"",(J$2-'Platzierungen alle Olympiaden'!$H11)/(J$2-1)) | K11: =IF('Platzierungen alle Olympiaden'!$I11=0,"",(K$2-'Platzierungen alle Olympiaden'!$I11)/(K$2-1)) -> 0.85714286 | L11: =IF('Platzierungen alle Olympiaden'!$J11=0,"",(L$2-'Platzierungen alle Olympiaden'!$J11)/(L$2-1)) | M11: =IF('Platzierungen alle Olympiaden'!$K11=0,"",(M$2-'Platzierungen alle Olympiaden'!$K11)/(M$2-1)) -> 0.42857143
B12: 9 | C12: =IF(ISNUMBER(Durchschnitt!$F12)=TRUE(),_xlfn.RANK.EQ(Durchschnitt!$F12,Durchschnitt!$F$4:$F$36,0),"") -> 12 | D12: Melli | E12: =COUNT(G12:M12) -> 4 | F12: =IF(Durchschnitt!$E12>=3,AVERAGE(G12:M12),"") -> 0.33928571 | G12: =IF('Platzierungen alle Olympiaden'!$E12=0,"",(G$2-'Platzierungen alle Olympiaden'!$E12)/(G$2-1)) | H12: =IF('Platzierungen alle Olympiaden'!$F12=0,"",(H$2-'Platzierungen alle Olympiaden'!$F12)/(H$2-1)) -> 0.5 | I12: =IF('Platzierungen alle Olympiaden'!$G12=0,"",(I$2-'Platzierungen alle Olympiaden'!$G12)/(I$2-1)) -> 0 | J12: =IF('Platzierungen alle Olympiaden'!$H12=0,"",(J$2-'Platzierungen alle Olympiaden'!$H12)/(J$2-1)) | K12: =IF('Platzierungen alle Olympiaden'!$I12=0,"",(K$2-'Platzierungen alle Olympiaden'!$I12)/(K$2-1)) -> 0.14285714 | L12: =IF('Platzierungen alle Olympiaden'!$J12=0,"",(L$2-'Platzierungen alle Olympiaden'!$J12)/(L$2-1)) | M12: =IF('Platzierungen alle Olympiaden'!$K12=0,"",(M$2-'Platzierungen alle Olympiaden'!$K12)/(M$2-1)) -> 0.71428571
B13: 10 | C13: =IF(ISNUMBER(Durchschnitt!$F13)=TRUE(),_xlfn.RANK.EQ(Durchschnitt!$F13,Durchschnitt!$F$4:$F$36,0),"") -> 7 | D13: Roman | E13: =COUNT(G13:M13) -> 3 | F13: =IF(Durchschnitt!$E13>=3,AVERAGE(G13:M13),"") -> 0.51190476 | G13: =IF('Platzierungen alle Olympiaden'!$E13=0,"",(G$2-'Platzierungen alle Olympiaden'!$E13)/(G$2-1)) | H13: =IF('Platzierungen alle Olympiaden'!$F13=0,"",(H$2-'Platzierungen alle Olympiaden'!$F13)/(H$2-1)) | I13: =IF('Platzierungen alle Olympiaden'!$G13=0,"",(I$2-'Platzierungen alle Olympiaden'!$G13)/(I$2-1)) -> 0.75 | J13: =IF('Platzierungen alle Olympiaden'!$H13=0,"",(J$2-'Platzierungen alle Olympiaden'!$H13)/(J$2-1)) | K13: =IF('Platzierungen alle Olympiaden'!$I13=0,"",(K$2-'Platzierungen alle Olympiaden'!$I13)/(K$2-1)) -> 0.28571429 | L13: =IF('Platzierungen alle Olympiaden'!$J13=0,"",(L$2-'Platzierungen alle Olympiaden'!$J13)/(L$2-1)) -> 0.5 | M13: =IF('Platzierungen alle Olympiaden'!$K13=0,"",(M$2-'Platzierungen alle Olympiaden'!$K13)/(M$2-1))
B14: 11 | C14: =IF(ISNUMBER(Durchschnitt!$F14)=TRUE(),_xlfn.RANK.EQ(Durchschnitt!$F14,Durchschnitt!$F$4:$F$36,0),"") -> 15 | D14: Robin | E14: =COUNT(G14:M14) -> 5 | F14: =IF(Durchschnitt!$E14>=3,AVERAGE(G14:M14),"") -> 0.225 | G14: =IF('Platzierungen alle Olympiaden'!$E14=0,"",(G$2-'Platzierungen alle Olympiaden'!$E14)/(G$2-1)) | H14: =IF('Platzierungen alle Olympiaden'!$F14=0,"",(H$2-'Platzierungen alle Olympiaden'!$F14)/(H$2-1)) -> 0.25 | I14: =IF('Platzierungen alle Olympiaden'!$G14=0,"",(I$2-'Platzierungen alle Olympiaden'!$G14)/(I$2-1)) -> 0.5 | J14: =IF('Platzierungen alle Olympiaden'!$H14=0,"",(J$2-'Platzierungen alle Olympiaden'!$H14)/(J$2-1)) -> 0 | K14: =IF('Platzierungen alle Olympiaden'!$I14=0,"",(K$2-'Platzierungen alle Olympiaden'!$I14)/(K$2-1)) -> 0 | L14: =IF('Platzierungen alle Olympiaden'!$J14=0,"",(L$2-'Platzierungen alle Olympiaden'!$J14)/(L$2-1)) -> 0.375 | M14: =IF('Platzierungen alle Olympiaden'!$K14=0,"",(M$2-'Platzierungen alle Olympiaden'!$K14)/(M$2-1))
B15: 12 | C15: =IF(ISNUMBER(Durchschnitt!$F15)=TRUE(),_xlfn.RANK.EQ(Durchschnitt!$F15,Durchschnitt!$F$4:$F$36,0),"") | D15: Marc | E15: =COUNT(G15:M15) -> 2 | F15: =IF(Durchschnitt!$E15>=3,AVERAGE(G15:M15),"") | G15: =IF('Platzierungen alle Olympiaden'!$E15=0,"",(G$2-'Platzierungen alle Olympiaden'!$E15)/(G$2-1)) | H15: =IF('Platzierungen alle Olympiaden'!$F15=0,"",(H$2-'Platzierungen alle Olympiaden'!$F15)/(H$2-1)) | I15: =IF('Platzierungen alle Olympiaden'!$G15=0,"",(I$2-'Platzierungen alle Olympiaden'!$G15)/(I$2-1)) | J15: =IF('Platzierungen alle Olympiaden'!$H15=0,"",(J$2-'Platzierungen alle Olympiaden'!$H15)/(J$2-1)) | K15: =IF('Platzierungen alle Olympiaden'!$I15=0,"",(K$2-'Platzierungen alle Olympiaden'!$I15)/(K$2-1)) | L15: =IF('Platzierungen alle Olympiaden'!$J15=0,"",(L$2-'Platzierungen alle Olympiaden'!$J15)/(L$2-1)) -> 0.875 | M15: =IF('Platzierungen alle Olympiaden'!$K15=0,"",(M$2-'Platzierungen alle Olympiaden'!$K15)/(M$2-1)) -> 0.28571429
... B36: 33 | C36: =IF(ISNUMBER(Durchschnitt!$F36)=TRUE(),_xlfn.RANK.EQ(Durchschnitt!$F36,Durchschnitt!$F$4:$F$36,0),"") | D36: Charlie | E36: =COUNT(G36:M36) -> 1 | F36: =IF(Durchschnitt!$E36>=3,AVERAGE(G36:M36),"") | G36: =IF('Platzierungen alle Olympiaden'!$E36=0,"",(G$2-'Platzierungen alle Olympiaden'!$E36)/(G$2-1)) | H36: =IF('Platzierungen alle Olympiaden'!$F36=0,"",(H$2-'Platzierungen alle Olympiaden'!$F36)/(H$2-1)) | I36: =IF('Platzierungen alle Olympiaden'!$G36=0,"",(I$2-'Platzierungen alle Olympiaden'!$G36)/(I$2-1)) | J36: =IF('Platzierungen alle Olympiaden'!$H36=0,"",(J$2-'Platzierungen alle Olympiaden'!$H36)/(J$2-1)) | K36: =IF('Platzierungen alle Olympiaden'!$I36=0,"",(K$2-'Platzierungen alle Olympiaden'!$I36)/(K$2-1)) -> 0 | L36: =IF('Platzierungen alle Olympiaden'!$J36=0,"",(L$2-'Platzierungen alle Olympiaden'!$J36)/(L$2-1)) | M36: =IF('Platzierungen alle Olympiaden'!$K36=0,"",(M$2-'Platzierungen alle Olympiaden'!$K36)/(M$2-1))

Sheet Medaillen
A1: Platzierung | B1: Name | C1: Flunkyball_1st | D1: Flunkyball_2nd | E1: Flunkyball_3rd | F1: Flunkyball_Gesamt | G1: Beerpong_1st | H1: Beerpong_2nd | I1: Beerpong_3rd | J1: Beerpong_Gesamt | K1: Flipcup_1st | L1: Flipcup_2nd | M1: Flipcup_3rd | N1: Flipcup_Gesamt | O1: Platz_1st | P1: Platz_2nd | Q1: Platz_3rd | R1: Platz_Gesamt | S1: Gesamt_1st | T1: Gesamt_2nd | U1: Gesamt_3rd | V1: Gesamt_Gesamt | W1: Gesamtpunkte | X1: Durchschnittspunkte_Gesamt
A2: 2 | B2: Richard | C2: =COUNTIFS(Olympiade_1!$B:$B,$B2,Olympiade_1!$F:$F,1)+COUNTIFS(Olympiade_2!$B:$B,$B2,Olympiade_2!$F:$F,1)+COUNTIFS(Olympiade_3!$B:$B,$B2,Olympiade_3!$F:$F,1)+COUNTIFS(Olympiade_4!$B:$B,$B2,Olympiade_4!$F:$F,1)+COUNTIFS(Olympiade_5!$B:$B,$B2,Olympiade_5!$F:$F,1)+COUNTIFS(Olympiade_6!$B:$B,$B2,Olympiade_6!$F:$F,1)+COUNTIFS(Olympiade_7!$B:$B,$B2,Olympiade_7!$F:$F,1)+COUNTIFS(Olympiade_8!$B:$B,$B2,Olympiade_8!$F:$F,1) -> 3 | D2: =COUNTIFS(Olympiade_1!$B:$B, $B2, Olympiade_1!$F:$F,2)+COUNTIFS(Olympiade_2!$B:$B, $B2, Olympiade_2!$F:$F,2)+COUNTIFS(Olympiade_3!$B:$B, $B2, Olympiade_3!$F:$F,2)+COUNTIFS(Olympiade_4!$B:$B, $B2, Olympiade_4!$F:$F,2)+COUNTIFS(Olympiade_5!$B:$B, $B2, Olympiade_5!$F:$F,2)+COUNTIFS(Olympiade_6!$B:$B, $B2, Olympiade_6!$F:$F,2)+COUNTIFS(Olympiade_7!$B:$B, $B2, Olympiade_7!$F:$F,2)+COUNTIFS(Olympiade_8!$B:$B, $B2, Olympiade_8!$F:$F,2) -> 1 | E2: =COUNTIFS(Olympiade_1!$B:$B, $B2, Olympiade_1!$F:$F,3)+COUNTIFS(Olympiade_2!$B:$B, $B2, Olympiade_2!$F:$F,3)+COUNTIFS(Olympiade_3!$B:$B, $B2, Olympiade_3!$F:$F,3)+COUNTIFS(Olympiade_4!$B:$B, $B2, Olympiade_4!$F:$F,3)+COUNTIFS(Olympiade_5!$B:$B, $B2, Olympiade_5!$F:$F,3)+COUNTIFS(Olympiade_6!$B:$B, $B2, Olympiade_6!$F:$F,3)+COUNTIFS(Olympiade_7!$B:$B, $B2, Olympiade_7!$F:$F,3)+COUNTIFS(Olympiade_8!$B:$B, $B2, Olympiade_8!$F:$F,3) -> 0 | F2: =SUM(C2,D2,E2) -> 4 | G2: =COUNTIFS(Olympiade_1!$B:$B, $B2, Olympiade_1!$G:$G,1)+COUNTIFS(Olympiade_2!$B:$B, $B2, Olympiade_2!$G:$G,1)+COUNTIFS(Olympiade_3!$B:$B, $B2, Olympiade_3!$G:$G,1)+COUNTIFS(Olympiade_4!$B:$B, $B2, Olympiade_4!$G:$G,1)+COUNTIFS(Olympiade_5!$B:$B, $B2, Olympiade_5!$G:$G,1)+COUNTIFS(Olympiade_6!$B:$B, $B2, Olympiade_6!$G:$G,1)+COUNTIFS(Olympiade_7!$B:$B, $B2, Olympiade_7!$G:$G,1)+COUNTIFS(Olympiade_8!$B:$B, $B2, Olympiade_8!$G:$G,1) -> 2 | H2: =COUNTIFS(Olympiade_1!$B:$B, $B2, Olympiade_1!$G:$G,2)+COUNTIFS(Olympiade_2!$B:$B, $B2, Olympiade_2!$G:$G,2)+COUNTIFS(Olympiade_3!$B:$B, $B2, Olympiade_3!$G:$G,2)+COUNTIFS(Olympiade_4!$B:$B, $B2, Olympiade_4!$G:$G,2)+COUNTIFS(Olympiade_5!$B:$B, $B2, Olympiade_5!$G:$G,2)+COUNTIFS(Olympiade_6!$B:$B, $B2, Olympiade_6!$G:$G,2)+COUNTIFS(Olympiade_7!$B:$B, $B2, Olympiade_7!$G:$G,2)+COUNTIFS(Olympiade_8!$B:$B, $B2, Olympiade_8!$G:$G,2) -> 2 | I2: =COUNTIFS(Olympiade_1!$B:$B, $B2, Olympiade_1!$G:$G,3)+COUNTIFS(Olympiade_2!$B:$B, $B2, Olympiade_2!$G:$G,3)+COUNTIFS(Olympiade_3!$B:$B, $B2, Olympiade_3!$G:$G,3)+COUNTIFS(Olympiade_4!$B:$B, $B2, Olympiade_4!$G:$G,3)+COUNTIFS(Olympiade_5!$B:$B, $B2, Olympiade_5!$G:$G,3)+COUNTIFS(Olympiade_6!$B:$B, $B2, Olympiade_6!$G:$G,3)+COUNTIFS(Olympiade_7!$B:$B, $B2, Olympiade_7!$G:$G,3)+COUNTIFS(Olympiade_8!$B:$B, $B2, Olympiade_8!$G:$G,3) -> 2 | J2: =SUM(G2,H2,I2) -> 6 | K2: =COUNTIFS(Olympiade_1!$B:$B, $B2, Olympiade_1!$H:$H,1)+COUNTIFS(Olympiade_2!$B:$B, $B2, Olympiade_2!$H:$H,1)+COUNTIFS(Olympiade_3!$B:$B, $B2, Olympiade_3!$H:$H,1)+COUNTIFS(Olympiade_4!$B:$B, $B2, Olympiade_4!$H:$H,1)+COUNTIFS(Olympiade_5!$B:$B, $B2, Olympiade_5!$H:$H,1)+COUNTIFS(Olympiade_6!$B:$B, $B2, Olympiade_6!$H:$H,1)+COUNTIFS(Olympiade_7!$B:$B, $B2, Olympiade_7!$H:$H,1)+COUNTIFS(Olympiade_8!$B:$B, $B2, Olympiade_8!$H:$H,1) -> 2 | L2: =COUNTIFS(Olympiade_1!$B:$B, $B2, Olympiade_1!$H:$H,2)+COUNTIFS(Olympiade_2!$B:$B, $B2, Olympiade_2!$H:$H,2)+COUNTIFS(Olympiade_3!$B:$B, $B2, Olympiade_3!$H:$H,2)+COUNTIFS(Olympiade_4!$B:$B, $B2, Olympiade_4!$H:$H,2)+COUNTIFS(Olympiade_5!$B:$B, $B2, Olympiade_5!$H:$H,2)+COUNTIFS(Olympiade_6!$B:$B, $B2, Olympiade_6!$H:$H,2)+COUNTIFS(Olympiade_7!$B:$B, $B2, Olympiade_7!$H:$H,2)+COUNTIFS(Olympiade_8!$B:$B, $B2, Olympiade_8!$H:$H,2) -> 1 | M2: =COUNTIFS(Olympiade_1!$B:$B, $B2, Olympiade_1!$H:$H,3)+COUNTIFS(Olympiade_2!$B:$B, $B2, Olympiade_2!$H:$H,3)+COUNTIFS(Olympiade_3!$B:$B, $B2, Olympiade_3!$H:$H,3)+COUNTIFS(Olympiade_4!$B:$B, $B2, Olympiade_4!$H:$H,3)+COUNTIFS(Olympiade_5!$B:$B, $B2, Olympiade_5!$H:$H,3)+COUNTIFS(Olympiade_6!$B:$B, $B2, Olympiade_6!$H:$H,3)+COUNTIFS(Olympiade_7!$B:$B, $B2, Olympiade_7!$H:$H,3)+COUNTIFS(Olympiade_8!$B:$B, $B2, Olympiade_8!$H:$H,3) -> 1 | N2: =SUM(K2,L2,M2) -> 4 | O2: =COUNTIFS(Olympiade_1!$B:$B, $B2, Olympiade_1!$A:$A,1)+COUNTIFS(Olympiade_2!$B:$B, $B2, Olympiade_2!$A:$A,1)+COUNTIFS(Olympiade_3!$B:$B, $B2, Olympiade_3!$A:$A,1)+COUNTIFS(Olympiade_4!$B:$B, $B2, Olympiade_4!$A:$A,1)+COUNTIFS(Olympiade_5!$B:$B, $B2, Olympiade_5!$A:$A,1)+COUNTIFS(Olympiade_6!$B:$B, $B2, Olympiade_6!$A:$A,1)+COUNTIFS(Olympiade_7!$B:$B, $B2, Olympiade_7!$A:$A,1)+COUNTIFS(Olympiade_8!$B:$B, $B2, Olympiade_8!$A:$A,1) -> 4 | P2: =COUNTIFS(Olympiade_1!$B:$B, $B2, Olympiade_1!$A:$A,2)+COUNTIFS(Olympiade_2!$B:$B, $B2, Olympiade_2!$A:$A,2)+COUNTIFS(Olympiade_3!$B:$B, $B2, Olympiade_3!$A:$A,2)+COUNTIFS(Olympiade_4!$B:$B, $B2, Olympiade_4!$A:$A,2)+COUNTIFS(Olympiade_5!$B:$B, $B2, Olympiade_5!$A:$A,2)+COUNTIFS(Olympiade_6!$B:$B, $B2, Olympiade_6!$A:$A,2)+COUNTIFS(Olympiade_7!$B:$B, $B2, Olympiade_7!$A:$A,2)+COUNTIFS(Olympiade_8!$B:$B, $B2, Olympiade_8!$A:$A,2) -> 1 | Q2: =COUNTIFS(Olympiade_1!$B:$B, $B2, Olympiade_1!$A:$A,3)+COUNTIFS(Olympiade_2!$B:$B, $B2, Olympiade_2!$A:$A,3)+COUNTIFS(Olympiade_3!$B:$B, $B2, Olympiade_3!$A:$A,3)+COUNTIFS(Olympiade_4!$B:$B, $B2, Olympiade_4!$A:$A,3)+COUNTIFS(Olympiade_5!$B:$B, $B2, Olympiade_5!$A:$A,3)+COUNTIFS(Olympiade_6!$B:$B, $B2, Olympiade_6!$A:$A,3)+COUNTIFS(Olympiade_7!$B:$B, $B2, Olympiade_7!$A:$A,3)+COUNTIFS(Olympiade_8!$B:$B, $B2, Olympiade_8!$A:$A,3) -> 0 | R2: =SUM(O2,P2,Q2) -> 5 | S2: =SUM(C2,G2,K2,O2) -> 11 | T2: =SUM(D2,H2,L2,P2) -> 5 | U2: =SUM(E2,I2,M2,Q2) -> 3 | V2: =SUM(S2,T2,U2) -> 19 | W2: =SUMIFS(Database!B:B,Database!A:A,B2) + SUMIFS(Database!F:F,Database!A:A,B2) -> 340 | X2: {=AVERAGE(xlookup(B2, Database!K:K, Database!L:N,NA()))} -> #N/A
A3: 6 | B3: Georg | C3: =COUNTIFS(Olympiade_1!$B:$B,$B3,Olympiade_1!$F:$F,1)+COUNTIFS(Olympiade_2!$B:$B,$B3,Olympiade_2!$F:$F,1)+COUNTIFS(Olympiade_3!$B:$B,$B3,Olympiade_3!$F:$F,1)+COUNTIFS(Olympiade_4!$B:$B,$B3,Olympiade_4!$F:$F,1)+COUNTIFS(Olympiade_5!$B:$B,$B3,Olympiade_5!$F:$F,1)+COUNTIFS(Olympiade_6!$B:$B,$B3,Olympiade_6!$F:$F,1)+COUNTIFS(Olympiade_7!$B:$B,$B3,Olympiade_7!$F:$F,1)+COUNTIFS(Olympiade_8!$B:$B,$B3,Olympiade_8!$F:$F,1) -> 3 | D3: =COUNTIFS(Olympiade_1!$B:$B, $B3, Olympiade_1!$F:$F,2)+COUNTIFS(Olympiade_2!$B:$B, $B3, Olympiade_2!$F:$F,2)+COUNTIFS(Olympiade_3!$B:$B, $B3, Olympiade_3!$F:$F,2)+COUNTIFS(Olympiade_4!$B:$B, $B3, Olympiade_4!$F:$F,2)+COUNTIFS(Olympiade_5!$B:$B, $B3, Olympiade_5!$F:$F,2)+COUNTIFS(Olympiade_6!$B:$B, $B3, Olympiade_6!$F:$F,2)+COUNTIFS(Olympiade_7!$B:$B, $B3, Olympiade_7!$F:$F,2)+COUNTIFS(Olympiade_8!$B:$B, $B3, Olympiade_8!$F:$F,2) -> 0 | E3: =COUNTIFS(Olympiade_1!$B:$B, $B3, Olympiade_1!$F:$F,3)+COUNTIFS(Olympiade_2!$B:$B, $B3, Olympiade_2!$F:$F,3)+COUNTIFS(Olympiade_3!$B:$B, $B3, Olympiade_3!$F:$F,3)+COUNTIFS(Olympiade_4!$B:$B, $B3, Olympiade_4!$F:$F,3)+COUNTIFS(Olympiade_5!$B:$B, $B3, Olympiade_5!$F:$F,3)+COUNTIFS(Olympiade_6!$B:$B, $B3, Olympiade_6!$F:$F,3)+COUNTIFS(Olympiade_7!$B:$B, $B3, Olympiade_7!$F:$F,3)+COUNTIFS(Olympiade_8!$B:$B, $B3, Olympiade_8!$F:$F,3) -> 0 | F3: =SUM(C3,D3,E3) -> 3 | G3: =COUNTIFS(Olympiade_1!$B:$B, $B3, Olympiade_1!$G:$G,1)+COUNTIFS(Olympiade_2!$B:$B, $B3, Olympiade_2!$G:$G,1)+COUNTIFS(Olympiade_3!$B:$B, $B3, Olympiade_3!$G:$G,1)+COUNTIFS(Olympiade_4!$B:$B, $B3, Olympiade_4!$G:$G,1)+COUNTIFS(Olympiade_5!$B:$B, $B3, Olympiade_5!$G:$G,1)+COUNTIFS(Olympiade_6!$B:$B, $B3, Olympiade_6!$G:$G,1)+COUNTIFS(Olympiade_7!$B:$B, $B3, Olympiade_7!$G:$G,1)+COUNTIFS(Olympiade_8!$B:$B, $B3, Olympiade_8!$G:$G,1) -> 1 | H3: =COUNTIFS(Olympiade_1!$B:$B, $B3, Olympiade_1!$G:$G,2)+COUNTIFS(Olympiade_2!$B:$B, $B3, Olympiade_2!$G:$G,2)+COUNTIFS(Olympiade_3!$B:$B, $B3, Olympiade_3!$G:$G,2)+COUNTIFS(Olympiade_4!$B:$B, $B3, Olympiade_4!$G:$G,2)+COUNTIFS(Olympiade_5!$B:$B, $B3, Olympiade_5!$G:$G,2)+COUNTIFS(Olympiade_6!$B:$B, $B3, Olympiade_6!$G:$G,2)+COUNTIFS(Olympiade_7!$B:$B, $B3, Olympiade_7!$G:$G,2)+COUNTIFS(Olympiade_8!$B:$B, $B3, Olympiade_8!$G:$G,2) -> 2 | I3: =COUNTIFS(Olympiade_1!$B:$B, $B3, Olympiade_1!$G:$G,3)+COUNTIFS(Olympiade_2!$B:$B, $B3, Olympiade_2!$G:$G,3)+COUNTIFS(Olympiade_3!$B:$B, $B3, Olympiade_3!$G:$G,3)+COUNTIFS(Olympiade_4!$B:$B, $B3, Olympiade_4!$G:$G,3)+COUNTIFS(Olympiade_5!$B:$B, $B3, Olympiade_5!$G:$G,3)+COUNTIFS(Olympiade_6!$B:$B, $B3, Olympiade_6!$G:$G,3)+COUNTIFS(Olympiade_7!$B:$B, $B3, Olympiade_7!$G:$G,3)+COUNTIFS(Olympiade_8!$B:$B, $B3, Olympiade_8!$G:$G,3) -> 1 | J3: =SUM(G3,H3,I3) -> 4 | K3: =COUNTIFS(Olympiade_1!$B:$B, $B3, Olympiade_1!$H:$H,1)+COUNTIFS(Olympiade_2!$B:$B, $B3, Olympiade_2!$H:$H,1)+COUNTIFS(Olympiade_3!$B:$B, $B3, Olympiade_3!$H:$H,1)+COUNTIFS(Olympiade_4!$B:$B, $B3, Olympiade_4!$H:$H,1)+COUNTIFS(Olympiade_5!$B:$B, $B3, Olympiade_5!$H:$H,1)+COUNTIFS(Olympiade_6!$B:$B, $B3, Olympiade_6!$H:$H,1)+COUNTIFS(Olympiade_7!$B:$B, $B3, Olympiade_7!$H:$H,1)+COUNTIFS(Olympiade_8!$B:$B, $B3, Olympiade_8!$H:$H,1) -> 1 | L3: =COUNTIFS(Olympiade_1!$B:$B, $B3, Olympiade_1!$H:$H,2)+COUNTIFS(Olympiade_2!$B:$B, $B3, Olympiade_2!$H:$H,2)+COUNTIFS(Olympiade_3!$B:$B, $B3, Olympiade_3!$H:$H,2)+COUNTIFS(Olympiade_4!$B:$B, $B3, Olympiade_4!$H:$H,2)+COUNTIFS(Olympiade_5!$B:$B, $B3, Olympiade_5!$H:$H,2)+COUNTIFS(Olympiade_6!$B:$B, $B3, Olympiade_6!$H:$H,2)+COUNTIFS(Olympiade_7!$B:$B, $B3, Olympiade_7!$H:$H,2)+COUNTIFS(Olympiade_8!$B:$B, $B3, Olympiade_8!$H:$H,2) -> 3 | M3: =COUNTIFS(Olympiade_1!$B:$B, $B3, Olympiade_1!$H:$H,3)+COUNTIFS(Olympiade_2!$B:$B, $B3, Olympiade_2!$H:$H,3)+COUNTIFS(Olympiade_3!$B:$B, $B3, Olympiade_3!$H:$H,3)+COUNTIFS(Olympiade_4!$B:$B, $B3, Olympiade_4!$H:$H,3)+COUNTIFS(Olympiade_5!$B:$B, $B3, Olympiade_5!$H:$H,3)+COUNTIFS(Olympiade_6!$B:$B, $B3, Olympiade_6!$H:$H,3)+COUNTIFS(Olympiade_7!$B:$B, $B3, Olympiade_7!$H:$H,3)+COUNTIFS(Olympiade_8!$B:$B, $B3, Olympiade_8!$H:$H,3) -> 0 | N3: =SUM(K3,L3,M3) -> 4 | O3: =COUNTIFS(Olympiade_1!$B:$B, $B3, Olympiade_1!$A:$A,1)+COUNTIFS(Olympiade_2!$B:$B, $B3, Olympiade_2!$A:$A,1)+COUNTIFS(Olympiade_3!$B:$B, $B3, Olympiade_3!$A:$A,1)+COUNTIFS(Olympiade_4!$B:$B, $B3, Olympiade_4!$A:$A,1)+COUNTIFS(Olympiade_5!$B:$B, $B3, Olympiade_5!$A:$A,1)+COUNTIFS(Olympiade_6!$B:$B, $B3, Olympiade_6!$A:$A,1)+COUNTIFS(Olympiade_7!$B:$B, $B3, Olympiade_7!$A:$A,1)+COUNTIFS(Olympiade_8!$B:$B, $B3, Olympiade_8!$A:$A,1) -> 2 | P3: =COUNTIFS(Olympiade_1!$B:$B, $B3, Olympiade_1!$A:$A,2)+COUNTIFS(Olympiade_2!$B:$B, $B3, Olympiade_2!$A:$A,2)+COUNTIFS(Olympiade_3!$B:$B, $B3, Olympiade_3!$A:$A,2)+COUNTIFS(Olympiade_4!$B:$B, $B3, Olympiade_4!$A:$A,2)+COUNTIFS(Olympiade_5!$B:$B, $B3, Olympiade_5!$A:$A,2)+COUNTIFS(Olympiade_6!$B:$B, $B3, Olympiade_6!$A:$A,2)+COUNTIFS(Olympiade_7!$B:$B, $B3, Olympiade_7!$A:$A,2)+COUNTIFS(Olympiade_8!$B:$B, $B3, Olympiade_8!$A:$A,2) -> 1 | Q3: =COUNTIFS(Olympiade_1!$B:$B, $B3, Olympiade_1!$A:$A,3)+COUNTIFS(Olympiade_2!$B:$B, $B3, Olympiade_2!$A:$A,3)+COUNTIFS(Olympiade_3!$B:$B, $B3, Olympiade_3!$A:$A,3)+COUNTIFS(Olympiade_4!$B:$B, $B3, Olympiade_4!$A:$A,3)+COUNTIFS(Olympiade_5!$B:$B, $B3, Olympiade_5!$A:$A,3)+COUNTIFS(Olympiade_6!$B:$B, $B3, Olympiade_6!$A:$A,3)+COUNTIFS(Olympiade_7!$B:$B, $B3, Olympiade_7!$A:$A,3)+COUNTIFS(Olympiade_8!$B:$B, $B3, Olympiade_8!$A:$A,3) -> 1 | R3: =SUM(O3,P3,Q3) -> 4 | S3: =SUM(C3,G3,K3,O3) -> 7 | T3: =SUM(D3,H3,L3,P3) -> 6 | U3: =SUM(E3,I3,M3,Q3) -> 2 | V3: =SUM(S3,T3,U3) -> 15 | W3: =SUMIFS(Database!B:B,Database!A:A,B3) + SUMIFS(Database!F:F,Database!A:A,B3) -> 240 | X3: {=AVERAGE(xlookup(B3, Database!K:K, Database!L:N,NA()))} -> #N/A
A4: 5 | B4: Till | C4: =COUNTIFS(Olympiade_1!$B:$B,$B4,Olympiade_1!$F:$F,1)+COUNTIFS(Olympiade_2!$B:$B,$B4,Olympiade_2!$F:$F,1)+COUNTIFS(Olympiade_3!$B:$B,$B4,Olympiade_3!$F:$F,1)+COUNTIFS(Olympiade_4!$B:$B,$B4,Olympiade_4!$F:$F,1)+COUNTIFS(Olympiade_5!$B:$B,$B4,Olympiade_5!$F:$F,1)+COUNTIFS(Olympiade_6!$B:$B,$B4,Olympiade_6!$F:$F,1)+COUNTIFS(Olympiade_7!$B:$B,$B4,Olympiade_7!$F:$F,1)+COUNTIFS(Olympiade_8!$B:$B,$B4,Olympiade_8!$F:$F,1) -> 2 | D4: =COUNTIFS(Olympiade_1!$B:$B, $B4, Olympiade_1!$F:$F,2)+COUNTIFS(Olympiade_2!$B:$B, $B4, Olympiade_2!$F:$F,2)+COUNTIFS(Olympiade_3!$B:$B, $B4, Olympiade_3!$F:$F,2)+COUNTIFS(Olympiade_4!$B:$B, $B4, Olympiade_4!$F:$F,2)+COUNTIFS(Olympiade_5!$B:$B, $B4, Olympiade_5!$F:$F,2)+COUNTIFS(Olympiade_6!$B:$B, $B4, Olympiade_6!$F:$F,2)+COUNTIFS(Olympiade_7!$B:$B, $B4, Olympiade_7!$F:$F,2)+COUNTIFS(Olympiade_8!$B:$B, $B4, Olympiade_8!$F:$F,2) -> 1 | E4: =COUNTIFS(Olympiade_1!$B:$B, $B4, Olympiade_1!$F:$F,3)+COUNTIFS(Olympiade_2!$B:$B, $B4, Olympiade_2!$F:$F,3)+COUNTIFS(Olympiade_3!$B:$B, $B4, Olympiade_3!$F:$F,3)+COUNTIFS(Olympiade_4!$B:$B, $B4, Olympiade_4!$F:$F,3)+COUNTIFS(Olympiade_5!$B:$B, $B4, Olympiade_5!$F:$F,3)+COUNTIFS(Olympiade_6!$B:$B, $B4, Olympiade_6!$F:$F,3)+COUNTIFS(Olympiade_7!$B:$B, $B4, Olympiade_7!$F:$F,3)+COUNTIFS(Olympiade_8!$B:$B, $B4, Olympiade_8!$F:$F,3) -> 0 | F4: =SUM(C4,D4,E4) -> 3 | G4: =COUNTIFS(Olympiade_1!$B:$B, $B4, Olympiade_1!$G:$G,1)+COUNTIFS(Olympiade_2!$B:$B, $B4, Olympiade_2!$G:$G,1)+COUNTIFS(Olympiade_3!$B:$B, $B4, Olympiade_3!$G:$G,1)+COUNTIFS(Olympiade_4!$B:$B, $B4, Olympiade_4!$G:$G,1)+COUNTIFS(Olympiade_5!$B:$B, $B4, Olympiade_5!$G:$G,1)+COUNTIFS(Olympiade_6!$B:$B, $B4, Olympiade_6!$G:$G,1)+COUNTIFS(Olympiade_7!$B:$B, $B4, Olympiade_7!$G:$G,1)+COUNTIFS(Olympiade_8!$B:$B, $B4, Olympiade_8!$G:$G,1) -> 0 | H4: =COUNTIFS(Olympiade_1!$B:$B, $B4, Olympiade_1!$G:$G,2)+COUNTIFS(Olympiade_2!$B:$B, $B4, Olympiade_2!$G:$G,2)+COUNTIFS(Olympiade_3!$B:$B, $B4, Olympiade_3!$G:$G,2)+COUNTIFS(Olympiade_4!$B:$B, $B4, Olympiade_4!$G:$G,2)+COUNTIFS(Olympiade_5!$B:$B, $B4, Olympiade_5!$G:$G,2)+COUNTIFS(Olympiade_6!$B:$B, $B4, Olympiade_6!$G:$G,2)+COUNTIFS(Olympiade_7!$B:$B, $B4, Olympiade_7!$G:$G,2)+COUNTIFS(Olympiade_8!$B:$B, $B4, Olympiade_8!$G:$G,2) -> 1 | I4: =COUNTIFS(Olympiade_1!$B:$B, $B4, Olympiade_1!$G:$G,3)+COUNTIFS(Olympiade_2!$B:$B, $B4, Olympiade_2!$G:$G,3)+COUNTIFS(Olympiade_3!$B:$B, $B4, Olympiade_3!$G:$G,3)+COUNTIFS(Olympiade_4!$B:$B, $B4, Olympiade_4!$G:$G,3)+COUNTIFS(Olympiade_5!$B:$B, $B4, Olympiade_5!$G:$G,3)+COUNTIFS(Olympiade_6!$B:$B, $B4, Olympiade_6!$G:$G,3)+COUNTIFS(Olympiade_7!$B:$B, $B4, Olympiade_7!$G:$G,3)+COUNTIFS(Olympiade_8!$B:$B, $B4, Olympiade_8!$G:$G,3) -> 0 | J4: =SUM(G4,H4,I4) -> 1 | K4: =COUNTIFS(Olympiade_1!$B:$B, $B4, Olympiade_1!$H:$H,1)+COUNTIFS(Olympiade_2!$B:$B, $B4, Olympiade_2!$H:$H,1)+COUNTIFS(Olympiade_3!$B:$B, $B4, Olympiade_3!$H:$H,1)+COUNTIFS(Olympiade_4!$B:$B, $B4, Olympiade_4!$H:$H,1)+COUNTIFS(Olympiade_5!$B:$B, $B4, Olympiade_5!$H:$H,1)+COUNTIFS(Olympiade_6!$B:$B, $B4, Olympiade_6!$H:$H,1)+COUNTIFS(Olympiade_7!$B:$B, $B4, Olympiade_7!$H:$H,1)+COUNTIFS(Olympiade_8!$B:$B, $B4, Olympiade_8!$H:$H,1) -> 1 | L4: =COUNTIFS(Olympiade_1!$B:$B, $B4, Olympiade_1!$H:$H,2)+COUNTIFS(Olympiade_2!$B:$B, $B4, Olympiade_2!$H:$H,2)+COUNTIFS(Olympiade_3!$B:$B, $B4, Olympiade_3!$H:$H,2)+COUNTIFS(Olympiade_4!$B:$B, $B4, Olympiade_4!$H:$H,2)+COUNTIFS(Olympiade_5!$B:$B, $B4, Olympiade_5!$H:$H,2)+COUNTIFS(Olympiade_6!$B:$B, $B4, Olympiade_6!$H:$H,2)+COUNTIFS(Olympiade_7!$B:$B, $B4, Olympiade_7!$H:$H,2)+COUNTIFS(Olympiade_8!$B:$B, $B4, Olympiade_8!$H:$H,2) -> 1 | M4: =COUNTIFS(Olympiade_1!$B:$B, $B4, Olympiade_1!$H:$H,3)+COUNTIFS(Olympiade_2!$B:$B, $B4, Olympiade_2!$H:$H,3)+COUNTIFS(Olympiade_3!$B:$B, $B4, Olympiade_3!$H:$H,3)+COUNTIFS(Olympiade_4!$B:$B, $B4, Olympiade_4!$H:$H,3)+COUNTIFS(Olympiade_5!$B:$B, $B4, Olympiade_5!$H:$H,3)+COUNTIFS(Olympiade_6!$B:$B, $B4, Olympiade_6!$H:$H,3)+COUNTIFS(Olympiade_7!$B:$B, $B4, Olympiade_7!$H:$H,3)+COUNTIFS(Olympiade_8!$B:$B, $B4, Olympiade_8!$H:$H,3) -> 1 | N4: =SUM(K4,L4,M4) -> 3 | O4: =COUNTIFS(Olympiade_1!$B:$B, $B4, Olympiade_1!$A:$A,1)+COUNTIFS(Olympiade_2!$B:$B, $B4, Olympiade_2!$A:$A,1)+COUNTIFS(Olympiade_3!$B:$B, $B4, Olympiade_3!$A:$A,1)+COUNTIFS(Olympiade_4!$B:$B, $B4, Olympiade_4!$A:$A,1)+COUNTIFS(Olympiade_5!$B:$B, $B4, Olympiade_5!$A:$A,1)+COUNTIFS(Olympiade_6!$B:$B, $B4, Olympiade_6!$A:$A,1)+COUNTIFS(Olympiade_7!$B:$B, $B4, Olympiade_7!$A:$A,1)+COUNTIFS(Olympiade_8!$B:$B, $B4, Olympiade_8!$A:$A,1) -> 2 | P4: =COUNTIFS(Olympiade_1!$B:$B, $B4, Olympiade_1!$A:$A,2)+COUNTIFS(Olympiade_2!$B:$B, $B4, Olympiade_2!$A:$A,2)+COUNTIFS(Olympiade_3!$B:$B, $B4, Olympiade_3!$A:$A,2)+COUNTIFS(Olympiade_4!$B:$B, $B4, Olympiade_4!$A:$A,2)+COUNTIFS(Olympiade_5!$B:$B, $B4, Olympiade_5!$A:$A,2)+COUNTIFS(Olympiade_6!$B:$B, $B4, Olympiade_6!$A:$A,2)+COUNTIFS(Olympiade_7!$B:$B, $B4, Olympiade_7!$A:$A,2)+COUNTIFS(Olympiade_8!$B:$B, $B4, Olympiade_8!$A:$A,2) -> 1 | Q4: =COUNTIFS(Olympiade_1!$B:$B, $B4, Olympiade_1!$A:$A,3)+COUNTIFS(Olympiade_2!$B:$B, $B4, Olympiade_2!$A:$A,3)+COUNTIFS(Olympiade_3!$B:$B, $B4, Olympiade_3!$A:$A,3)+COUNTIFS(Olympiade_4!$B:$B, $B4, Olympiade_4!$A:$A,3)+COUNTIFS(Olympiade_5!$B:$B, $B4, Olympiade_5!$A:$A,3)+COUNTIFS(Olympiade_6!$B:$B, $B4, Olympiade_6!$A:$A,3)+COUNTIFS(Olympiade_7!$B:$B, $B4, Olympiade_7!$A:$A,3)+COUNTIFS(Olympiade_8!$B:$B, $B4, Olympiade_8!$A:$A,3) -> 0 | R4: =SUM(O4,P4,Q4) -> 3 | S4: =SUM(C4,G4,K4,O4) -> 5 | T4: =SUM(D4,H4,L4,P4) -> 4 | U4: =SUM(E4,I4,M4,Q4) -> 1 | V4: =SUM(S4,T4,U4) -> 10 | W4: =SUMIFS(Database!B:B,Database!A:A,B4) + SUMIFS(Database!F:F,Database!A:A,B4) -> 260 | X4: {=AVERAGE(xlookup(B4, Database!K:K, Database!L:N,NA()))} -> #N/A
A5: 4 | B5: Hannah | C5: =COUNTIFS(Olympiade_1!$B:$B,$B5,Olympiade_1!$F:$F,1)+COUNTIFS(Olympiade_2!$B:$B,$B5,Olympiade_2!$F:$F,1)+COUNTIFS(Olympiade_3!$B:$B,$B5,Olympiade_3!$F:$F,1)+COUNTIFS(Olympiade_4!$B:$B,$B5,Olympiade_4!$F:$F,1)+COUNTIFS(Olympiade_5!$B:$B,$B5,Olympiade_5!$F:$F,1)+COUNTIFS(Olympiade_6!$B:$B,$B5,Olympiade_6!$F:$F,1)+COUNTIFS(Olympiade_7!$B:$B,$B5,Olympiade_7!$F:$F,1)+COUNTIFS(Olympiade_8!$B:$B,$B5,Olympiade_8!$F:$F,1) -> 0 | D5: =COUNTIFS(Olympiade_1!$B:$B, $B5, Olympiade_1!$F:$F,2)+COUNTIFS(Olympiade_2!$B:$B, $B5, Olympiade_2!$F:$F,2)+COUNTIFS(Olympiade_3!$B:$B, $B5, Olympiade_3!$F:$F,2)+COUNTIFS(Olympiade_4!$B:$B, $B5, Olympiade_4!$F:$F,2)+COUNTIFS(Olympiade_5!$B:$B, $B5, Olympiade_5!$F:$F,2)+COUNTIFS(Olympiade_6!$B:$B, $B5, Olympiade_6!$F:$F,2)+COUNTIFS(Olympiade_7!$B:$B, $B5, Olympiade_7!$F:$F,2)+COUNTIFS(Olympiade_8!$B:$B, $B5, Olympiade_8!$F:$F,2) -> 0 | E5: =COUNTIFS(Olympiade_1!$B:$B, $B5, Olympiade_1!$F:$F,3)+COUNTIFS(Olympiade_2!$B:$B, $B5, Olympiade_2!$F:$F,3)+COUNTIFS(Olympiade_3!$B:$B, $B5, Olympiade_3!$F:$F,3)+COUNTIFS(Olympiade_4!$B:$B, $B5, Olympiade_4!$F:$F,3)+COUNTIFS(Olympiade_5!$B:$B, $B5, Olympiade_5!$F:$F,3)+COUNTIFS(Olympiade_6!$B:$B, $B5, Olympiade_6!$F:$F,3)+COUNTIFS(Olympiade_7!$B:$B, $B5, Olympiade_7!$F:$F,3)+COUNTIFS(Olympiade_8!$B:$B, $B5, Olympiade_8!$F:$F,3) -> 2 | F5: =SUM(C5,D5,E5) -> 2 | G5: =COUNTIFS(Olympiade_1!$B:$B, $B5, Olympiade_1!$G:$G,1)+COUNTIFS(Olympiade_2!$B:$B, $B5, Olympiade_2!$G:$G,1)+COUNTIFS(Olympiade_3!$B:$B, $B5, Olympiade_3!$G:$G,1)+COUNTIFS(Olympiade_4!$B:$B, $B5, Olympiade_4!$G:$G,1)+COUNTIFS(Olympiade_5!$B:$B, $B5, Olympiade_5!$G:$G,1)+COUNTIFS(Olympiade_6!$B:$B, $B5, Olympiade_6!$G:$G,1)+COUNTIFS(Olympiade_7!$B:$B, $B5, Olympiade_7!$G:$G,1)+COUNTIFS(Olympiade_8!$B:$B, $B5, Olympiade_8!$G:$G,1) -> 0 | H5: =COUNTIFS(Olympiade_1!$B:$B, $B5, Olympiade_1!$G:$G,2)+COUNTIFS(Olympiade_2!$B:$B, $B5, Olympiade_2!$G:$G,2)+COUNTIFS(Olympiade_3!$B:$B, $B5, Olympiade_3!$G:$G,2)+COUNTIFS(Olympiade_4!$B:$B, $B5, Olympiade_4!$G:$G,2)+COUNTIFS(Olympiade_5!$B:$B, $B5, Olympiade_5!$G:$G,2)+COUNTIFS(Olympiade_6!$B:$B, $B5, Olympiade_6!$G:$G,2)+COUNTIFS(Olympiade_7!$B:$B, $B5, Olympiade_7!$G:$G,2)+COUNTIFS(Olympiade_8!$B:$B, $B5, Olympiade_8!$G:$G,2) -> 1 | I5: =COUNTIFS(Olympiade_1!$B:$B, $B5, Olympiade_1!$G:$G,3)+COUNTIFS(Olympiade_2!$B:$B, $B5, Olympiade_2!$G:$G,3)+COUNTIFS(Olympiade_3!$B:$B, $B5, Olympiade_3!$G:$G,3)+COUNTIFS(Olympiade_4!$B:$B, $B5, Olympiade_4!$G:$G,3)+COUNTIFS(Olympiade_5!$B:$B, $B5, Olympiade_5!$G:$G,3)+COUNTIFS(Olympiade_6!$B:$B, $B5, Olympiade_6!$G:$G,3)+COUNTIFS(Olympiade_7!$B:$B, $B5, Olympiade_7!$G:$G,3)+COUNTIFS(Olympiade_8!$B:$B, $B5, Olympiade_8!$G:$G,3) -> 1 | J5: =SUM(G5,H5,I5) -> 2 | K5: =COUNTIFS(Olympiade_1!$B:$B, $B5, Olympiade_1!$H:$H,1)+COUNTIFS(Olympiade_2!$B:$B, $B5, Olympiade_2!$H:$H,1)+COUNTIFS(Olympiade_3!$B:$B, $B5, Olympiade_3!$H:$H,1)+COUNTIFS(Olympiade_4!$B:$B, $B5, Olympiade_4!$H:$H,1)+COUNTIFS(Olympiade_5!$B:$B, $B5, Olympiade_5!$H:$H,1)+COUNTIFS(Olympiade_6!$B:$B, $B5, Olympiade_6!$H:$H,1)+COUNTIFS(Olympiade_7!$B:$B, $B5, Olympiade_7!$H:$H,1)+COUNTIFS(Olympiade_8!$B:$B, $B5, Olympiade_8!$H:$H,1) -> 3 | L5: =COUNTIFS(Olympiade_1!$B:$B, $B5, Olympiade_1!$H:$H,2)+COUNTIFS(Olympiade_2!$B:$B, $B5, Olympiade_2!$H:$H,2)+COUNTIFS(Olympiade_3!$B:$B, $B5, Olympiade_3!$H:$H,2)+COUNTIFS(Olympiade_4!$B:$B, $B5, Olympiade_4!$H:$H,2)+COUNTIFS(Olympiade_5!$B:$B, $B5, Olympiade_5!$H:$H,2)+COUNTIFS(Olympiade_6!$B:$B, $B5, Olympiade_6!$H:$H,2)+COUNTIFS(Olympiade_7!$B:$B, $B5, Olympiade_7!$H:$H,2)+COUNTIFS(Olympiade_8!$B:$B, $B5, Olympiade_8!$H:$H,2) -> 1 | M5: =COUNTIFS(Olympiade_1!$B:$B, $B5, Olympiade_1!$H:$H,3)+COUNTIFS(Olympiade_2!$B:$B, $B5, Olympiade_2!$H:$H,3)+COUNTIFS(Olympiade_3!$B:$B, $B5, Olympiade_3!$H:$H,3)+COUNTIFS(Olympiade_4!$B:$B, $B5, Olympiade_4!$H:$H,3)+COUNTIFS(Olympiade_5!$B:$B, $B5, Olympiade_5!$H:$H,3)+COUNTIFS(Olympiade_6!$B:$B, $B5, Olympiade_6!$H:$H,3)+COUNTIFS(Olympiade_7!$B:$B, $B5, Olympiade_7!$H:$H,3)+COUNTIFS(Olympiade_8!$B:$B, $B5, Olympiade_8!$H:$H,3) -> 2 | N5: =SUM(K5,L5,M5) -> 6 | O5: =COUNTIFS(Olympiade_1!$B:$B, $B5, Olympiade_1!$A:$A,1)+COUNTIFS(Olympiade_2!$B:$B, $B5, Olympiade_2!$A:$A,1)+COUNTIFS(Olympiade_3!$B:$B, $B5, Olympiade_3!$A:$A,1)+COUNTIFS(Olympiade_4!$B:$B, $B5, Olympiade_4!$A:$A,1)+COUNTIFS(Olympiade_5!$B:$B, $B5, Olympiade_5!$A:$A,1)+COUNTIFS(Olympiade_6!$B:$B, $B5, Olympiade_6!$A:$A,1)+COUNTIFS(Olympiade_7!$B:$B, $B5, Olympiade_7!$A:$A,1)+COUNTIFS(Olympiade_8!$B:$B, $B5, Olympiade_8!$A:$A,1) -> 2 | P5: =COUNTIFS(Olympiade_1!$B:$B, $B5, Olympiade_1!$A:$A,2)+COUNTIFS(Olympiade_2!$B:$B, $B5, Olympiade_2!$A:$A,2)+COUNTIFS(Olympiade_3!$B:$B, $B5, Olympiade_3!$A:$A,2)+COUNTIFS(Olympiade_4!$B:$B, $B5, Olympiade_4!$A:$A,2)+COUNTIFS(Olympiade_5!$B:$B, $B5, Olympiade_5!$A:$A,2)+COUNTIFS(Olympiade_6!$B:$B, $B5, Olympiade_6!$A:$A,2)+COUNTIFS(Olympiade_7!$B:$B, $B5, Olympiade_7!$A:$A,2)+COUNTIFS(Olympiade_8!$B:$B, $B5, Olympiade_8!$A:$A,2) -> 0 | Q5: =COUNTIFS(Olympiade_1!$B:$B, $B5, Olympiade_1!$A:$A,3)+COUNTIFS(Olympiade_2!$B:$B, $B5, Olympiade_2!$A:$A,3)+COUNTIFS(Olympiade_3!$B:$B, $B5, Olympiade_3!$A:$A,3)+COUNTIFS(Olympiade_4!$B:$B, $B5, Olympiade_4!$A:$A,3)+COUNTIFS(Olympiade_5!$B:$B, $B5, Olympiade_5!$A:$A,3)+COUNTIFS(Olympiade_6!$B:$B, $B5, Olympiade_6!$A:$A,3)+COUNTIFS(Olympiade_7!$B:$B, $B5, Olympiade_7!$A:$A,3)+COUNTIFS(Olympiade_8!$B:$B, $B5, Olympiade_8!$A:$A,3) -> 1 | R5: =SUM(O5,P5,Q5) -> 3 | S5: =SUM(C5,G5,K5,O5) -> 5 | T5: =SUM(D5,H5,L5,P5) -> 2 | U5: =SUM(E5,I5,M5,Q5) -> 6 | V5: =SUM(S5,T5,U5) -> 13 | W5: =SUMIFS(Database!B:B,Database!A:A,B5) + SUMIFS(Database!F:F,Database!A:A,B5) -> 270 | X5: {=AVERAGE(xlookup(B5, Database!K:K, Database!L:N,NA()))} -> #N/A
A6: 3 | B6: Jannes | C6: =COUNTIFS(Olympiade_1!$B:$B,$B6,Olympiade_1!$F:$F,1)+COUNTIFS(Olympiade_2!$B:$B,$B6,Olympiade_2!$F:$F,1)+COUNTIFS(Olympiade_3!$B:$B,$B6,Olympiade_3!$F:$F,1)+COUNTIFS(Olympiade_4!$B:$B,$B6,Olympiade_4!$F:$F,1)+COUNTIFS(Olympiade_5!$B:$B,$B6,Olympiade_5!$F:$F,1)+COUNTIFS(Olympiade_6!$B:$B,$B6,Olympiade_6!$F:$F,1)+COUNTIFS(Olympiade_7!$B:$B,$B6,Olympiade_7!$F:$F,1)+COUNTIFS(Olympiade_8!$B:$B,$B6,Olympiade_8!$F:$F,1) -> 1 | D6: =COUNTIFS(Olympiade_1!$B:$B, $B6, Olympiade_1!$F:$F,2)+COUNTIFS(Olympiade_2!$B:$B, $B6, Olympiade_2!$F:$F,2)+COUNTIFS(Olympiade_3!$B:$B, $B6, Olympiade_3!$F:$F,2)+COUNTIFS(Olympiade_4!$B:$B, $B6, Olympiade_4!$F:$F,2)+COUNTIFS(Olympiade_5!$B:$B, $B6, Olympiade_5!$F:$F,2)+COUNTIFS(Olympiade_6!$B:$B, $B6, Olympiade_6!$F:$F,2)+COUNTIFS(Olympiade_7!$B:$B, $B6, Olympiade_7!$F:$F,2)+COUNTIFS(Olympiade_8!$B:$B, $B6, Olympiade_8!$F:$F,2) -> 1 | E6: =COUNTIFS(Olympiade_1!$B:$B, $B6, Olympiade_1!$F:$F,3)+COUNTIFS(Olympiade_2!$B:$B, $B6, Olympiade_2!$F:$F,3)+COUNTIFS(Olympiade_3!$B:$B, $B6, Olympiade_3!$F:$F,3)+COUNTIFS(Olympiade_4!$B:$B, $B6, Olympiade_4!$F:$F,3)+COUNTIFS(Olympiade_5!$B:$B, $B6, Olympiade_5!$F:$F,3)+COUNTIFS(Olympiade_6!$B:$B, $B6, Olympiade_6!$F:$F,3)+COUNTIFS(Olympiade_7!$B:$B, $B6, Olympiade_7!$F:$F,3)+COUNTIFS(Olympiade_8!$B:$B, $B6, Olympiade_8!$F:$F,3) -> 0 | F6: =SUM(C6,D6,E6) -> 2 | G6: =COUNTIFS(Olympiade_1!$B:$B, $B6, Olympiade_1!$G:$G,1)+COUNTIFS(Olympiade_2!$B:$B, $B6, Olympiade_2!$G:$G,1)+COUNTIFS(Olympiade_3!$B:$B, $B6, Olympiade_3!$G:$G,1)+COUNTIFS(Olympiade_4!$B:$B, $B6, Olympiade_4!$G:$G,1)+COUNTIFS(Olympiade_5!$B:$B, $B6, Olympiade_5!$G:$G,1)+COUNTIFS(Olympiade_6!$B:$B, $B6, Olympiade_6!$G:$G,1)+COUNTIFS(Olympiade_7!$B:$B, $B6, Olympiade_7!$G:$G,1)+COUNTIFS(Olympiade_8!$B:$B, $B6, Olympiade_8!$G:$G,1) -> 3 | H6: =COUNTIFS(Olympiade_1!$B:$B, $B6, Olympiade_1!$G:$G,2)+COUNTIFS(Olympiade_2!$B:$B, $B6, Olympiade_2!$G:$G,2)+COUNTIFS(Olympiade_3!$B:$B, $B6, Olympiade_3!$G:$G,2)+COUNTIFS(Olympiade_4!$B:$B, $B6, Olympiade_4!$G:$G,2)+COUNTIFS(Olympiade_5!$B:$B, $B6, Olympiade_5!$G:$G,2)+COUNTIFS(Olympiade_6!$B:$B, $B6, Olympiade_6!$G:$G,2)+COUNTIFS(Olympiade_7!$B:$B, $B6, Olympiade_7!$G:$G,2)+COUNTIFS(Olympiade_8!$B:$B, $B6, Olympiade_8!$G:$G,2) -> 0 | I6: =COUNTIFS(Olympiade_1!$B:$B, $B6, Olympiade_1!$G:$G,3)+COUNTIFS(Olympiade_2!$B:$B, $B6, Olympiade_2!$G:$G,3)+COUNTIFS(Olympiade_3!$B:$B, $B6, Olympiade_3!$G:$G,3)+COUNTIFS(Olympiade_4!$B:$B, $B6, Olympiade_4!$G:$G,3)+COUNTIFS(Olympiade_5!$B:$B, $B6, Olympiade_5!$G:$G,3)+COUNTIFS(Olympiade_6!$B:$B, $B6, Olympiade_6!$G:$G,3)+COUNTIFS(Olympiade_7!$B:$B, $B6, Olympiade_7!$G:$G,3)+COUNTIFS(Olympiade_8!$B:$B, $B6, Olympiade_8!$G:$G,3) -> 0 | J6: =SUM(G6,H6,I6) -> 3 | K6: =COUNTIFS(Olympiade_1!$B:$B, $B6, Olympiade_1!$H:$H,1)+COUNTIFS(Olympiade_2!$B:$B, $B6, Olympiade_2!$H:$H,1)+COUNTIFS(Olympiade_3!$B:$B, $B6, Olympiade_3!$H:$H,1)+COUNTIFS(Olympiade_4!$B:$B, $B6, Olympiade_4!$H:$H,1)+COUNTIFS(Olympiade_5!$B:$B, $B6, Olympiade_5!$H:$H,1)+COUNTIFS(Olympiade_6!$B:$B, $B6, Olympiade_6!$H:$H,1)+COUNTIFS(Olympiade_7!$B:$B, $B6, Olympiade_7!$H:$H,1)+COUNTIFS(Olympiade_8!$B:$B, $B6, Olympiade_8!$H:$H,1) -> 1 | L6: =COUNTIFS(Olympiade_1!$B:$B, $B6, Olympiade_1!$H:$H,2)+COUNTIFS(Olympiade_2!$B:$B, $B6, Olympiade_2!$H:$H,2)+COUNTIFS(Olympiade_3!$B:$B, $B6, Olympiade_3!$H:$H,2)+COUNTIFS(Olympiade_4!$B:$B, $B6, Olympiade_4!$H:$H,2)+COUNTIFS(Olympiade_5!$B:$B, $B6, Olympiade_5!$H:$H,2)+COUNTIFS(Olympiade_6!$B:$B, $B6, Olympiade_6!$H:$H,2)+COUNTIFS(Olympiade_7!$B:$B, $B6, Olympiade_7!$H:$H,2)+COUNTIFS(Olympiade_8!$B:$B, $B6, Olympiade_8!$H:$H,2) -> 1 | M6: =COUNTIFS(Olympiade_1!$B:$B, $B6, Olympiade_1!$H:$H,3)+COUNTIFS(Olympiade_2!$B:$B, $B6, Olympiade_2!$H:$H,3)+COUNTIFS(Olympiade_3!$B:$B, $B6, Olympiade_3!$H:$H,3)+COUNTIFS(Olympiade_4!$B:$B, $B6, Olympiade_4!$H:$H,3)+COUNTIFS(Olympiade_5!$B:$B, $B6, Olympiade_5!$H:$H,3)+COUNTIFS(Olympiade_6!$B:$B, $B6, Olympiade_6!$H:$H,3)+COUNTIFS(Olympiade_7!$B:$B, $B6, Olympiade_7!$H:$H,3)+COUNTIFS(Olympiade_8!$B:$B, $B6, Olympiade_8!$H:$H,3) -> 0 | N6: =SUM(K6,L6,M6) -> 2 | O6: =COUNTIFS(Olympiade_1!$B:$B, $B6, Olympiade_1!$A:$A,1)+COUNTIFS(Olympiade_2!$B:$B, $B6, Olympiade_2!$A:$A,1)+COUNTIFS(Olympiade_3!$B:$B, $B6, Olympiade_3!$A:$A,1)+COUNTIFS(Olympiade_4!$B:$B, $B6, Olympiade_4!$A:$A,1)+COUNTIFS(Olympiade_5!$B:$B, $B6, Olympiade_5!$A:$A,1)+COUNTIFS(Olympiade_6!$B:$B, $B6, Olympiade_6!$A:$A,1)+COUNTIFS(Olympiade_7!$B:$B, $B6, Olympiade_7!$A:$A,1)+COUNTIFS(Olympiade_8!$B:$B, $B6, Olympiade_8!$A:$A,1) -> 1 | P6: =COUNTIFS(Olympiade_1!$B:$B, $B6, Olympiade_1!$A:$A,2)+COUNTIFS(Olympiade_2!$B:$B, $B6, Olympiade_2!$A:$A,2)+COUNTIFS(Olympiade_3!$B:$B, $B6, Olympiade_3!$A:$A,2)+COUNTIFS(Olympiade_4!$B:$B, $B6, Olympiade_4!$A:$A,2)+COUNTIFS(Olympiade_5!$B:$B, $B6, Olympiade_5!$A:$A,2)+COUNTIFS(Olympiade_6!$B:$B, $B6, Olympiade_6!$A:$A,2)+COUNTIFS(Olympiade_7!$B:$B, $B6, Olympiade_7!$A:$A,2)+COUNTIFS(Olympiade_8!$B:$B, $B6, Olympiade_8!$A:$A,2) -> 2 | Q6: =COUNTIFS(Olympiade_1!$B:$B, $B6, Olympiade_1!$A:$A,3)+COUNTIFS(Olympiade_2!$B:$B, $B6, Olympiade_2!$A:$A,3)+COUNTIFS(Olympiade_3!$B:$B, $B6, Olympiade_3!$A:$A,3)+COUNTIFS(Olympiade_4!$B:$B, $B6, Olympiade_4!$A:$A,3)+COUNTIFS(Olympiade_5!$B:$B, $B6, Olympiade_5!$A:$A,3)+COUNTIFS(Olympiade_6!$B:$B, $B6, Olympiade_6!$A:$A,3)+COUNTIFS(Olympiade_7!$B:$B, $B6, Olympiade_7!$A:$A,3)+COUNTIFS(Olympiade_8!$B:$B, $B6, Olympiade_8!$A:$A,3) -> 1 | R6: =SUM(O6,P6,Q6) -> 4 | S6: =SUM(C6,G6,K6,O6) -> 6 | T6: =SUM(D6,H6,L6,P6) -> 4 | U6: =SUM(E6,I6,M6,Q6) -> 1 | V6: =SUM(S6,T6,U6) -> 11 | W6: =SUMIFS(Database!B:B,Database!A:A,B6) + SUMIFS(Database!F:F,Database!A:A,B6) -> 300 | X6: {=AVERAGE(xlookup(B6, Database!K:K, Database!L:N,NA()))} -> #N/A
